<?xml version="1.0"?>
<robot name="dtw_robot" xmlns:xacro="http://ros.org/wiki/xacro">
    <material name="gray">
        <color rgba="0.5 0.5 0.5 2.5"/>
    </material>
    <material name="red">
        <color rgba="1.0 0.0 0.0 2.0"/>
    </material>
    <material name="white">
        <color rgba="0.5 0.0 2.5 2.0"/>
    </material>

    <xacro:macro name="flipper_left_macro" params="parent suffix xyz">
        <joint name="${suffix}_joint" type="revolute">
            <parent link="${parent}"/>
            <child  link="${suffix}_link"/>
            <origin xyz="${xyz}" rpy="0 0 ${radians(-90)}"/>
            <limit lower="-1.5" upper="1.5" effort="0" velocity="0"/>
        </joint>
        <link name="${suffix}_link">
            <visual>
                <geometry>
                  <mesh filename="package://gui/stl/flipper.stl"/>
                </geometry>
                <origin xyz="0.02 0 0.038" rpy="0 0 0"/>
                <material name="red"/>
            </visual>
        </link>
    </xacro:macro>

    <xacro:macro name="flipper_right_macro" params="parent suffix xyz">
        <joint name="${suffix}_joint" type="revolute">
            <parent link="${parent}"/>
            <child  link="${suffix}_link"/>
            <origin xyz="${xyz}" rpy="0 0 ${radians(-90)}"/>
            <limit lower="-1.5" upper="1.5" effort="0" velocity="0"/>
        </joint>
        <link name="${suffix}_link">
            <visual>
                <geometry>
                  <mesh filename="package://gui/stl/flipper_another.stl"/>
                </geometry>
                <origin xyz="0.02 0 0.038" rpy="0 0 0"/>
                <material name="red"/>
            </visual>
        </link>
    </xacro:macro>

    <link name="base_link"/>

    <joint name="body_joint" type="fixed">
        <parent link="base_link"/>
        <child  link="body_link"/>
        <origin xyz="0 0 0" rpy="0 0 0"/>
    </joint>

    <link name="body_link" type="fixed">
        <visual>
            <origin xyz="0 0 0.035" rpy="0 0 0"/>
            <geometry>
              <mesh filename="package://gui/stl/main.stl"/>
            </geometry>
            <material name="red"/>
        </visual>
    </link>

    <xacro:flipper_right_macro suffix="front_right_flipper"  parent="base_link" xyz="0.0975 0.125 0.026"/>
    <xacro:flipper_left_macro suffix="front_left_flipper" parent="base_link" xyz="0.0975 -0.084 0.026"/>
    <xacro:flipper_right_macro suffix="rear_right_flipper" parent="base_link" xyz="-0.0975 0.125 0.026"/>
    <xacro:flipper_left_macro suffix="rear_left_flipper" parent="base_link" xyz="-0.0970 -0.084 0.027"/>
</robot>
